<robot name="mobile_robot">

<link name="body_link" />
<link name="wheel1_link" />
<link name="wheel2_link" />
<link name="wheel3_link" />
<link name="wheel4_link" />

<joint name="wheel1_joint" type="continuous"> 
    <parent link="body_link"/>
    <child link="wheel1_link"/>
</joint>

<joint name="wheel2_joint" type="continuous"> 
    <parent link="body_link"/>
    <child link="wheel2_link"/>
</joint>

<joint name="wheel3_joint" type="continuous"> 
    <parent link="body_link"/>
    <child link="wheel3_link"/>
</joint>

<joint name="wheel4_joint" type="continuous"> 
    <parent link="body_link"/>
    <child link="wheel4_link"/>
</joint>

</robot>